<?xml version="1.0" encoding="utf-8"?>

<!-- =================================================================================== -->
<!-- |    @uthor Min Htet Han ( ROM Robotics )                                         | -->
<!-- |    ROS Simulation Online Course                                                 | -->
<!-- =================================================================================== -->

<robot
  name="mobile_manipulation"> 
  "



  <gazebo reference="base_link">
	<material>Gazebo/Grey</material>
 </gazebo>

  <!-- <gazebo reference="base_link">
	<material>Gazebo/Grey2</material>
 </gazebo>

 <gazebo reference="link1">
	<material>Gazebo/Grey2</material>
 </gazebo>

 <gazebo reference="link2">
	<material>Gazebo/Grey2</material>
 </gazebo>

 <gazebo reference="arm_link3">
	<material>Gazebo/Grey2</material>
 </gazebo>

 <gazebo reference="arm_link3_two">
	<material>Gazebo/Lighton</material>
 </gazebo> origin_value -0.0081959 0.0004066 0.34679  
			-->
  <link
    name="base_link">
    <inertial>
      <origin
        xyz="-0.0081959 0.0004066 0.34679"   
        rpy="0 0 0" />
      <mass
        value="596.36" />
      <inertia
        ixx="68.349"
        ixy="0.13008"
        ixz="0.90766"
        iyy="118.4"
        iyz="-0.055438"
        izz="168.61" />
    </inertial>
    <visual>
      <origin
        xyz="0 0 0"
        rpy="0 0 0" />
      <geometry>
        <mesh
          filename="package://mh_han_simulation_ws/meshes/mobile_manipulation/base_link.dae" />
      </geometry>
      <material
        name="">
        <color
          rgba="0.79216 0.81961 0.93333 1" />
      </material>
    </visual>
    <collision>
      <origin
        xyz="0 0 0"
        rpy="0 0 0" />
      <geometry>
        <mesh
          filename="package://mh_han_simulation_ws/meshes/mobile_manipulation/base_link.dae" />
      </geometry>
    </collision>
  </link>
  <link
    name="right_back_wheel">
    <inertial>
      <origin
        xyz="2.83320145122445E-10 0.042645349650015 2.79596568120155E-10"
        rpy="0 0 0" />
      <mass
        value="23.6279356986933" />
      <inertia
        ixx="0.31978156556764"
        ixy="4.44263663880047E-10"
        ixz="2.2826242031198E-11"
        iyy="0.510668301436143"
        iyz="2.8849706035778E-11"
        izz="0.319781565373917" />
    </inertial>
    <visual>
      <origin
        xyz="0 0 0"
        rpy="0 0 0" />
      <geometry>
        <mesh
          filename="package://mh_han_simulation_ws/meshes/mobile_manipulation/right_back_wheel.dae" />
      </geometry>
      <material
        name="">
        <color
          rgba="0.752941176470588 0.752941176470588 0.752941176470588 1" />
      </material>
    </visual>
    <collision>
      <origin
        xyz="0 0 0"
        rpy="0 0 0" />
      <geometry>
        <mesh
          filename="package://mh_han_simulation_ws/meshes/mobile_manipulation/right_back_wheel.dae" />
      </geometry>
    </collision>
  </link>
  <joint
    name="right_back_wheel_joint"
    type="continuous">
    <origin
      xyz="-0.45 -0.6524 0.225"
      rpy="0 0 0" />
    <parent
      link="base_link" />
    <child
      link="right_back_wheel" />
    <axis
      xyz="0 1 0" />
    <safety_controller
      k_velocity="0" />
  </joint>
  <link
    name="right_front_wheel">
    <inertial>
      <origin
        xyz="-2.85718781967148E-10 0.0426453496497294 -2.77365685974473E-10"
        rpy="0 0 0" />
      <mass
        value="23.6279356986993" />
      <inertia
        ixx="0.319781565083403"
        ixy="-5.09486662984689E-10"
        ixz="-5.00516936860795E-11"
        iyy="0.510668301123914"
        iyz="1.36637006916901E-10"
        izz="0.3197815651638" />
    </inertial>
    <visual>
      <origin
        xyz="0 0 0"
        rpy="0 0 0" />
      <geometry>
        <mesh
          filename="package://mh_han_simulation_ws/meshes/mobile_manipulation/right_front_wheel.dae" />
      </geometry>
      <material
        name="">
        <color
          rgba="0.752941176470588 0.752941176470588 0.752941176470588 1" />
      </material>
    </visual>
    <collision>
      <origin
        xyz="0 0 0"
        rpy="0 0 0" />
      <geometry>
        <mesh
          filename="package://mh_han_simulation_ws/meshes/mobile_manipulation/right_front_wheel.dae" />
      </geometry>
    </collision>
  </link>
  <joint
    name="right_front_wheel_joint"
    type="continuous">
    <origin
      xyz="0.45 -0.6524 0.225"
      rpy="0 0 0" />
    <parent
      link="base_link" />
    <child
      link="right_front_wheel" />
    <axis
      xyz="0 1 0" />
    <safety_controller
      k_velocity="0" />
  </joint>
  <link
    name="left_back_wheel">
    <inertial>
      <origin
        xyz="2.8297186815962E-10 -0.0426453496500543 -2.79917533596574E-10"
        rpy="0 0 0" />
      <mass
        value="23.6279356986924" />
      <inertia
        ixx="0.319781565567375"
        ixy="-4.4467036824892E-10"
        ixz="-2.32548433355088E-11"
        iyy="0.510668301436044"
        iyz="2.95292272030471E-11"
        izz="0.319781565373617" />
    </inertial>
    <visual>
      <origin
        xyz="0 0 0"
        rpy="0 0 0" />
      <geometry>
        <mesh
          filename="package://mh_han_simulation_ws/meshes/mobile_manipulation/left_back_wheel.dae" />
      </geometry>
      <material
        name="">
        <color
          rgba="0.752941176470588 0.752941176470588 0.752941176470588 1" />
      </material>
    </visual>
    <collision>
      <origin
        xyz="0 0 0"
        rpy="0 0 0" />
      <geometry>
        <mesh
          filename="package://mh_han_simulation_ws/meshes/mobile_manipulation/left_back_wheel.dae" />
      </geometry>
    </collision>
  </link>
  <joint
    name="left_back_wheel_joint"
    type="continuous">
    <origin
      xyz="-0.45 0.6524 0.225"
      rpy="0 0 0" />
    <parent
      link="base_link" />
    <child
      link="left_back_wheel" />
    <axis
      xyz="0 1 0" />
    <safety_controller
      k_velocity="0" />
  </joint>
  <link
    name="left_front_wheel">
    <inertial>
      <origin
        xyz="2.82972090204225E-10 -0.0426453496500552 -2.79916312351247E-10"
        rpy="0 0 0" />
      <mass
        value="23.6279356986924" />
      <inertia
        ixx="0.319781565567375"
        ixy="-4.44670372077509E-10"
        ixz="-2.32548434468936E-11"
        iyy="0.510668301436044"
        iyz="2.95292271793301E-11"
        izz="0.319781565373617" />
    </inertial>
    <visual>
      <origin
        xyz="0 0 0"
        rpy="0 0 0" />
      <geometry>
        <mesh
          filename="package://mh_han_simulation_ws/meshes/mobile_manipulation/left_front_wheel.dae" />
      </geometry>
      <material
        name="">
        <color
          rgba="0.752941176470588 0.752941176470588 0.752941176470588 1" />
      </material>
    </visual>
    <collision>
      <origin
        xyz="0 0 0"
        rpy="0 0 0" />
      <geometry>
        <mesh
          filename="package://mh_han_simulation_ws/meshes/mobile_manipulation/left_front_wheel.dae" />
      </geometry>
    </collision>
  </link>
  <joint
    name="left_front_wheel_joint"
    type="continuous">
    <origin
      xyz="0.45 0.6524 0.225"
      rpy="0 0 0" />
    <parent
      link="base_link" />
    <child
      link="left_front_wheel" />
    <axis
      xyz="0 1 0" />
    <safety_controller
      k_velocity="0" />
  </joint>
<!--   <link
    name="arm_link1">
    <inertial>
      <origin
        xyz="-0.00114610008763694 -0.0104275132972207 0.256822875177275"
        rpy="0 0 0" />
      <mass
        value="0.4288513559643" />
      <inertia
        ixx="0.923258602381502"
        ixy="-0.00177430954572451"
        ixz="0.00689786848135409"
        iyy="0.907258756216452"
        iyz="0.0633353544414437"
        izz="0.147628057729936" />
    </inertial>
    <visual>
      <origin
        xyz="0 0 0"
        rpy="0 0 0" />
      <geometry>
        <mesh
          filename="package://mh_han_simulation_ws/meshes/mobile_manipulation/arm_link1.STL" />
      </geometry>
      <material
        name="">
        <color
          rgba="0.792156862745098 0.819607843137255 0.933333333333333 1" />
      </material>
    </visual>
    <collision>
      <origin
        xyz="0 0 0"
        rpy="0 0 0" />
      <geometry>
        <mesh
          filename="package://mh_han_simulation_ws/meshes/mobile_manipulation/arm_link1.STL" />
      </geometry>
    </collision>
  </link--> 
  <joint
    name="joint1"
    type="revolute">
    <origin
      xyz="0.5 0 0.8"
      rpy="0 0 0" />
    <parent
      link="base_link" />
    <child
      link="link1" />
    <axis
      xyz="0 0 1" />
    <limit effort="500" velocity="100" lower="-3.14" upper="3.14"/>
    
  </joint> 
  <link name="link1">
	<collision>
		<origin xyz="0 0 0" rpy="0 0 0"/>
		<geometry>
			<mesh
          	filename="package://mh_han_simulation_ws/5dof_arm_meshes/5dof_arm_link1.STL" />
		</geometry>
	</collision>

	<visual>
		<origin xyz="0 0 0" rpy="0 0 0"/>
		<geometry>
			<mesh
          	filename="package://mh_han_simulation_ws/5dof_arm_meshes/5dof_arm_link1.STL" />
		</geometry>
	</visual>

	<inertial>
		<origin xyz="0 0 0" rpy="0 0 0"/>
		<mass
        value="0.18241" />
      <inertia
        ixx="0.00026632"
        ixy="0"
        ixz="3.8327E-28"
        iyy="0.00026632"
        iyz="1.4704E-28"
        izz="0.00052959" />
	</inertial>
</link>

<gazebo reference="link1">
	<material>Gazebo/Grey</material>
</gazebo>

<!-- link2 and its revolute joint2 relative to link1 -->
<!-- rotating along y axis -->
<joint name="joint2" type="revolute">
	<parent link="link1"/>
	<child link="link2"/>
	<origin xyz="0.0 0 0.3" rpy="0 0 0"/>
	<axis xyz="0 1 0"/>
	<limit effort="500" velocity="100" lower="-0.1" upper="1.5708"/>
</joint>

<link name="link2">
	<collision>
		<origin xyz="0 0 0" rpy="0 0 1.57"/>
		<geometry>
			<mesh
          	filename="package://mh_han_simulation_ws/5dof_arm_meshes/5dof_arm_link2.STL" />
		</geometry>
	</collision>

	<visual>
		<origin xyz="0 0 0" rpy="0 0 1.57"/>
		<geometry>
			<mesh
          	filename="package://mh_han_simulation_ws/5dof_arm_meshes/5dof_arm_link2.STL" />
		</geometry>
	</visual>

	<inertial>
		<origin xyz="0 0 0.5" rpy="0 0 0"/>
		<mass
        value="0.18241" />
      <inertia
        ixx="0.00026632"
        ixy="0"
        ixz="3.8327E-28"
        iyy="0.00026632"
        iyz="1.4704E-28"
        izz="0.00052959" />
	</inertial>
</link>

<gazebo reference="link2">
	<material>Gazebo/Grey</material>
</gazebo>

<!-- link3 and its revolute joint3 relative to link2 -->
<!-- rotating along y axis -->
<joint name="joint3" type="revolute">
	<parent link="link2"/>
	<child link="link3"/>
	<origin xyz="0 0 1" rpy="0 0 0"/>
	<axis xyz="0 1 0"/>
	<limit effort="500" velocity="100" lower="-0.1" upper="3.1416"/>
</joint>

<link name="link3">
	<collision>
		<origin xyz="0 0 0" rpy="0 0 1.57"/>
		<geometry>
			<mesh
          	filename="package://mh_han_simulation_ws/5dof_arm_meshes/5dof_arm_link3.STL" />
		</geometry>
	</collision>

	<visual>
		<origin xyz="0 0 0" rpy="0 0 1.57"/>
		<geometry>
			<mesh
          	filename="package://mh_han_simulation_ws/5dof_arm_meshes/5dof_arm_link3.STL" />
		</geometry>
	</visual>

	<inertial>
		<origin xyz="0 0 0.5" rpy="0 0 0"/>
		<mass
        value="0.18241" />
      <inertia
        ixx="0.00026632"
        ixy="0"
        ixz="3.8327E-28"
        iyy="0.00026632"
        iyz="1.4704E-28"
        izz="0.00052959" />
	</inertial>
</link>


<link name="link3_to_4">
	<collision>
		<origin xyz="0 0 0.64" rpy="0 0 1.57"/>
		<geometry>
			<mesh
          	filename="package://mh_han_simulation_ws/5dof_arm_meshes/5dof_arm_link4.STL" />
		</geometry>
	</collision>

	<visual>
		<origin xyz="0 0 0.64" rpy="0 0 1.57"/>
		<geometry>
			<mesh
          	filename="package://mh_han_simulation_ws/5dof_arm_meshes/5dof_arm_link4.STL" />
		</geometry>
	</visual>

	<inertial>
		<origin xyz="0 0 0.5" rpy="0 0 0"/>
		<mass
        value="0.18241" />
      <inertia
        ixx="0.00026632"
        ixy="0"
        ixz="3.8327E-28"
        iyy="0.00026632"
        iyz="1.4704E-28"
        izz="0.00052959" />
	</inertial>
</link>

<joint name="joint3_two" type="fixed">
	<parent link="link3"/>
	<child link="link3_to_4"/>
	<origin xyz="0 0 -0.65" rpy="0 0 0"/>
	<axis xyz="0 0 0"/>
	<limit effort="500" velocity="100" lower="-0.1" upper="3.1416"/>
</joint>


<gazebo reference="link3">
	<material>Gazebo/Grey</material>
</gazebo>

<!-- link4 and its revolute joint4 relative to link3 -->
<!-- rotating along y axis -->
<joint name="joint4" type="revolute">
	<parent link="link3_to_4"/>
	<child link="link4"/>
	<origin xyz="0 0 1.65" rpy="0 0 0"/>
	<axis xyz="0 1 0"/>
	<limit effort="1000" velocity="100" lower="-1.5708" upper="1.5708"/>
</joint>

<link name="link4">
	<collision>
		<origin xyz="0 0 0" rpy="0 -1.57 0"/>
		<geometry>
			<mesh
          	filename="package://mh_han_simulation_ws/5dof_arm_meshes/5dof_arm_link5.STL" />
		</geometry>
	</collision>

	<visual>
		<origin xyz="0 0 0" rpy="0 -1.57 0"/>
		<geometry>
			<mesh
          	filename="package://mh_han_simulation_ws/5dof_arm_meshes/5dof_arm_link5.STL" />
		</geometry>
	</visual>

	<inertial>
		<origin xyz="0 0 0" rpy="1.5708 0 0"/>
		<mass value="0.4"/>
		<inertia
			ixx="0.05" ixy="0.0" ixz="0.0"
			iyy="0.002" iyz="0.0"
			izz="0.05"/>
	</inertial>
</link>

<gazebo reference="link4">
	<material>Gazebo/Red</material>
</gazebo>

<!-- link5 and its prismatic joint5 relative to link4 -->
<!-- translating along y axis -->
<joint name="joint5" type="prismatic">
	<parent link="link4"/>
	<child link="link5"/>
	<origin xyz="0 0.16 0" rpy="0 0 0"/>
	<axis xyz="0 1 0"/>
	<limit effort="1000" velocity="100" lower="-0.16" upper="0.0"/>
</joint>

<link name="link5">
	<collision>
		<origin xyz="0.01 0 0" rpy="-1.57 -1.57 0"/>
		<geometry>
			<mesh
          	filename="package://mh_han_simulation_ws/5dof_arm_meshes/5dof_arm_gripper.STL" />
		</geometry>
	</collision>

	<visual>
		<origin xyz="0.01 0 0" rpy="-1.57 -1.57 0"/>
		<geometry>
			<mesh
          	filename="package://mh_han_simulation_ws/5dof_arm_meshes/5dof_arm_gripper.STL" />
		</geometry>
	</visual>

	<inertial>
		<origin xyz="0 0 0.15" rpy="0 0 0"/>
		<mass value="0.2"/>
		<inertia
			ixx="0.02" ixy="0.0" ixz="0.0"
			iyy="0.02" iyz="0.0"
			izz="0.001"/>
	</inertial>
</link>

<gazebo reference="link5">
	<material>Gazebo/Red</material>
</gazebo>

<!-- link6 and its prismatic joint6 relative to link4 -->
<!-- translating along y axis -->
<joint name="joint6" type="prismatic">
	<parent link="link4"/>
	<child link="link6"/>
	<origin xyz="0 -0.16 0" rpy="0 0 0"/>
	<axis xyz="0 1 0"/>
	<limit effort="1000" velocity="100" lower="0.0" upper="0.16"/>
</joint>

<link name="link6">
	<collision>
		<origin xyz="0 0 0" rpy="0 -1.57 1.57"/>
		<geometry>
			<mesh
          	filename="package://mh_han_simulation_ws/5dof_arm_meshes/5dof_arm_gripper.STL" />
		</geometry>
	</collision>

	<visual>
		<origin xyz="0 0 0" rpy="0 -1.57 1.57"/>
		<geometry>
			<mesh
          	filename="package://mh_han_simulation_ws/5dof_arm_meshes/5dof_arm_gripper.STL" />
		</geometry>
	</visual>

	<inertial>
		<origin xyz="0 0 0.15" rpy="0 0 0"/>
		<mass value="0.2"/>
		<inertia
			ixx="0.02" ixy="0.0" ixz="0.0"
			iyy="0.02" iyz="0.0"
			izz="0.001"/>
	</inertial>
</link>

<gazebo reference="link6">
	<material>Gazebo/Red</material>
</gazebo>


 
  <link name="kinect_link">
	<collision>
		<origin xyz="0.85 0 0.26" rpy="0 0 1.57"/>
		<geometry>
			<mesh
          	filename="package://mh_han_simulation_ws/meshes/mobile_manipulation/mobile_manipulation_kinect.STL" />
		</geometry>
	</collision>

	<visual>
		<origin xyz="0.85 0 0.26" rpy="0 0 1.57"/>
		<geometry>
			<mesh
          	filename="package://mh_han_simulation_ws/meshes/mobile_manipulation/mobile_manipulation_kinect.STL" />
		</geometry>
	</visual>

	<inertial>
		<origin xyz="0 0 0" rpy="0 0 0"/>
		<mass
        value="0.18241" />
      <inertia
        ixx="0.00026632"
        ixy="0"
        ixz="3.8327E-28"
        iyy="0.00026632"
        iyz="1.4704E-28"
        izz="0.00052959" />
	</inertial>
</link>

<joint name="kinect_joint" type="fixed">
	<parent link="base_link"/>
	<child link="kinect_link"/>
	<origin xyz="0 0 0" rpy="0 0 0"/>
	<axis xyz="0 0 0"/>
	
</joint>

<link name="lidar_link">
	<collision>
		<origin xyz="0 0 0.6" rpy="0 0 0"/>
		<geometry>
			<mesh
          	filename="package://mh_han_simulation_ws/meshes/mobile_manipulation/mobile_manipulation_lidar.STL" />
		</geometry>
	</collision>

	<visual>
		<origin xyz="0 0 0.6" rpy="0 0 0"/>
		<geometry>
			<mesh
          	filename="package://mh_han_simulation_ws/meshes/mobile_manipulation/mobile_manipulation_lidar.STL" />
		</geometry>
	</visual>

	<inertial>
		<origin xyz="0 0 0" rpy="0 0 0"/>
		<mass
        value="0.18241" />
      <inertia
        ixx="0.00026632"
        ixy="0"
        ixz="3.8327E-28"
        iyy="0.00026632"
        iyz="1.4704E-28"
        izz="0.00052959" />
	</inertial>
</link>

<joint name="lidar_joint" type="continuous">
	<parent link="base_link"/>
	<child link="lidar_link"/>
	<origin xyz="0 0 0" rpy="0 0 0"/>
	<axis xyz="0 0 1"/>
	<limit effort="1000" velocity="100"/>
	
</joint>

<gazebo reference="lidar_link">   
    <material>Gazebo/Blue</material>
    <turnGravityOff>false</turnGravityOff>
    <sensor name="chassis_hokuyo_sensor" type="ray">
      <pose>0.025 0 0.6 0 0 0</pose>
      <visualize>false</visualize>
      <update_rate>40</update_rate>
      <ray>
        <scan>
          <horizontal>
            <samples>720</samples>
            <resolution>1</resolution>
            <min_angle>-3.57</min_angle>
            <max_angle>3.57</max_angle>
          </horizontal>
        </scan>
        <range>
          <min>0.50</min>
          <max>10.0</max>
          <resolution>1.0</resolution>
        </range>
      </ray>
      <plugin filename="libgazebo_ros_laser.so" name="gazebo_ros_head_hokuyo_controller">
        <topicName>/scan</topicName>
        <frameName>lidar_link</frameName>
      </plugin>
    </sensor>
  </gazebo>


    <transmission name="tran1">
    <type>transmission_interface/SimpleTransmission</type>
    <joint name="joint1">
      <hardwareInterface>hardware_interface/EffortJointInterface</hardwareInterface>
    </joint>
    <actuator name="motor1">
      <hardwareInterface>hardware_interface/EffortJointInterface</hardwareInterface>
      <mechanicalReduction>1</mechanicalReduction>
    </actuator>
  </transmission>
  <transmission name="tran2">
    <type>transmission_interface/SimpleTransmission</type>
    <joint name="joint2">
      <hardwareInterface>hardware_interface/EffortJointInterface</hardwareInterface>
    </joint>
    <actuator name="motor2">
      <hardwareInterface>hardware_interface/EffortJointInterface</hardwareInterface>
      <mechanicalReduction>1</mechanicalReduction>
    </actuator>
  </transmission>
  <transmission name="tran3">
    <type>transmission_interface/SimpleTransmission</type>
    <joint name="joint3">
      <hardwareInterface>hardware_interface/EffortJointInterface</hardwareInterface>
    </joint>
    <actuator name="motor3">
      <hardwareInterface>hardware_interface/EffortJointInterface</hardwareInterface>
      <mechanicalReduction>1</mechanicalReduction>
    </actuator>
  </transmission>
  <transmission name="tran4">
    <type>transmission_interface/SimpleTransmission</type>
    <joint name="joint4">
      <hardwareInterface>hardware_interface/EffortJointInterface</hardwareInterface>
    </joint>
    <actuator name="motor4">
      <hardwareInterface>hardware_interface/EffortJointInterface</hardwareInterface>
      <mechanicalReduction>1</mechanicalReduction>
    </actuator>
  </transmission>
  <transmission name="tran5">
    <type>transmission_interface/SimpleTransmission</type>
    <joint name="joint5">
      <hardwareInterface>hardware_interface/EffortJointInterface</hardwareInterface>
    </joint>
    <actuator name="motor5">
      <hardwareInterface>hardware_interface/EffortJointInterface</hardwareInterface>
      <mechanicalReduction>1</mechanicalReduction>
    </actuator>
  </transmission>
  <transmission name="tran6">
    <type>transmission_interface/SimpleTransmission</type>
    <joint name="joint6">
      <hardwareInterface>hardware_interface/EffortJointInterface</hardwareInterface>
    </joint>
    <actuator name="motor6">
      <hardwareInterface>hardware_interface/EffortJointInterface</hardwareInterface>
      <mechanicalReduction>1</mechanicalReduction>
    </actuator>
  </transmission>

  <transmission name="tran7">
    <type>transmission_interface/SimpleTransmission</type>
    <joint name="lidar_joint">
      <hardwareInterface>hardware_interface/EffortJointInterface</hardwareInterface>
    </joint>
    <actuator name="motor7">
      <hardwareInterface>hardware_interface/EffortJointInterface</hardwareInterface>
      <mechanicalReduction>1</mechanicalReduction>
    </actuator>
  </transmission>

   <gazebo>
    <plugin filename="libgazebo_ros_control.so" name="gazebo_ros_control">   	
      
    </plugin>
  </gazebo>

   <gazebo>
  <plugin name="skid_steer_drive_controller" filename="libgazebo_ros_skid_steer_drive.so">
    <updateRate>100.0</updateRate>
    <robotNamespace>/</robotNamespace>
    <leftFrontJoint>left_front_wheel_joint</leftFrontJoint>
    <rightFrontJoint>right_front_wheel_joint</rightFrontJoint>
    <leftRearJoint>left_back_wheel_joint</leftRearJoint>
    <rightRearJoint>right_back_wheel_joint</rightRearJoint>
    <wheelSeparation>1.3</wheelSeparation>
    <wheelDiameter>0.45</wheelDiameter>
    <robotBaseFrame>base_link</robotBaseFrame>
    <torque>500</torque>
    <topicName>cmd_vel</topicName>
    <broadcastTF>true</broadcastTF>
  </plugin>
</gazebo>

</robot>